package dyrewulf.citybiome.structures.fullchunk;

import net.minecraft.init.Blocks;
import net.minecraft.world.World;

public class Chapel implements FullChunkStructure
{

	@Override
	public void generate(World world, int xstart, int zstart, int xend, int zend)
	{
		
		int baseX = xstart + 1;
		int baseY = world.getTopSolidOrLiquidBlock(((xstart + (xend - xstart) / 2)), ((zstart + (zend - zstart) / 2))) - 1;
		int baseZ = zstart + 1;
		
		for(int i = 1; i < 14; i++)
		{
			for(int j = 1; j < 14; j++)
			{
				world.setBlock(baseX + i, baseY + 0, baseZ + j, Blocks.cobblestone, 0, 2);
				clearUp(world, baseX + i, baseY + 1, baseZ + j);
			}
		}
		
		
		world.setBlock(baseX + 0, baseY + 1, baseZ + 5, Blocks.stonebrick, 0, 2);
		world.setBlock(baseX + 0, baseY + 1, baseZ + 8, Blocks.stonebrick, 0, 2);
		world.setBlock(baseX + 0, baseY + 2, baseZ + 5, Blocks.stonebrick, 0, 2);
		world.setBlock(baseX + 0, baseY + 2, baseZ + 8, Blocks.stonebrick, 0, 2);
		world.setBlock(baseX + 0, baseY + 3, baseZ + 5, Blocks.stonebrick, 0, 2);
		world.setBlock(baseX + 0, baseY + 3, baseZ + 6, Blocks.stone_brick_stairs, 7, 2);
		world.setBlock(baseX + 0, baseY + 3, baseZ + 7, Blocks.stone_brick_stairs, 6, 2);
		world.setBlock(baseX + 0, baseY + 3, baseZ + 8, Blocks.stonebrick, 0, 2);
		world.setBlock(baseX + 0, baseY + 4, baseZ + 5, Blocks.stonebrick, 0, 2);
		world.setBlock(baseX + 0, baseY + 4, baseZ + 6, Blocks.stonebrick, 0, 2);
		world.setBlock(baseX + 0, baseY + 4, baseZ + 7, Blocks.stonebrick, 0, 2);
		world.setBlock(baseX + 0, baseY + 4, baseZ + 8, Blocks.stonebrick, 0, 2);
		world.setBlock(baseX + 0, baseY + 5, baseZ + 5, Blocks.stonebrick, 0, 2);
		world.setBlock(baseX + 0, baseY + 5, baseZ + 8, Blocks.stonebrick, 0, 2);
		world.setBlock(baseX + 0, baseY + 6, baseZ + 5, Blocks.stonebrick, 0, 2);
		world.setBlock(baseX + 0, baseY + 6, baseZ + 8, Blocks.stonebrick, 0, 2);
		world.setBlock(baseX + 0, baseY + 7, baseZ + 5, Blocks.stonebrick, 0, 2);
		world.setBlock(baseX + 0, baseY + 7, baseZ + 8, Blocks.stonebrick, 0, 2);
		world.setBlock(baseX + 0, baseY + 8, baseZ + 5, Blocks.stonebrick, 0, 2);
		world.setBlock(baseX + 0, baseY + 8, baseZ + 6, Blocks.stone_brick_stairs, 7, 2);
		world.setBlock(baseX + 0, baseY + 8, baseZ + 7, Blocks.stone_brick_stairs, 6, 2);
		world.setBlock(baseX + 0, baseY + 8, baseZ + 8, Blocks.stonebrick, 0, 2);
		world.setBlock(baseX + 0, baseY + 9, baseZ + 5, Blocks.stonebrick, 0, 2);
		world.setBlock(baseX + 0, baseY + 9, baseZ + 6, Blocks.stonebrick, 0, 2);
		world.setBlock(baseX + 0, baseY + 9, baseZ + 7, Blocks.stonebrick, 0, 2);
		world.setBlock(baseX + 0, baseY + 9, baseZ + 8, Blocks.stonebrick, 0, 2);
		world.setBlock(baseX + 1, baseY + 1, baseZ + 0, Blocks.stonebrick, 0, 2);
		world.setBlock(baseX + 1, baseY + 1, baseZ + 2, Blocks.stonebrick, 0, 2);
		world.setBlock(baseX + 1, baseY + 1, baseZ + 3, Blocks.stonebrick, 0, 2);
		world.setBlock(baseX + 1, baseY + 1, baseZ + 4, Blocks.stonebrick, 0, 2);
		world.setBlock(baseX + 1, baseY + 1, baseZ + 5, Blocks.stonebrick, 0, 2);
		world.setBlock(baseX + 1, baseY + 1, baseZ + 8, Blocks.stonebrick, 0, 2);
		world.setBlock(baseX + 1, baseY + 1, baseZ + 9, Blocks.stonebrick, 0, 2);
		world.setBlock(baseX + 1, baseY + 1, baseZ + 10, Blocks.stonebrick, 0, 2);
		world.setBlock(baseX + 1, baseY + 1, baseZ + 11, Blocks.stonebrick, 0, 2);
		world.setBlock(baseX + 1, baseY + 1, baseZ + 13, Blocks.stonebrick, 0, 2);
		world.setBlock(baseX + 1, baseY + 2, baseZ + 0, Blocks.stonebrick, 0, 2);
		world.setBlock(baseX + 1, baseY + 2, baseZ + 2, Blocks.stonebrick, 0, 2);
		world.setBlock(baseX + 1, baseY + 2, baseZ + 3, Blocks.stonebrick, 0, 2);
		world.setBlock(baseX + 1, baseY + 2, baseZ + 4, Blocks.stonebrick, 0, 2);
		world.setBlock(baseX + 1, baseY + 2, baseZ + 5, Blocks.stonebrick, 0, 2);
		world.setBlock(baseX + 1, baseY + 2, baseZ + 8, Blocks.stonebrick, 0, 2);
		world.setBlock(baseX + 1, baseY + 2, baseZ + 9, Blocks.stonebrick, 0, 2);
		world.setBlock(baseX + 1, baseY + 2, baseZ + 10, Blocks.stonebrick, 0, 2);
		world.setBlock(baseX + 1, baseY + 2, baseZ + 11, Blocks.stonebrick, 0, 2);
		world.setBlock(baseX + 1, baseY + 2, baseZ + 13, Blocks.stonebrick, 0, 2);
		world.setBlock(baseX + 1, baseY + 3, baseZ + 0, Blocks.stonebrick, 0, 2);
		world.setBlock(baseX + 1, baseY + 3, baseZ + 2, Blocks.stonebrick, 0, 2);
		world.setBlock(baseX + 1, baseY + 3, baseZ + 5, Blocks.stonebrick, 0, 2);
		world.setBlock(baseX + 1, baseY + 3, baseZ + 6, Blocks.stonebrick, 0, 2);
		world.setBlock(baseX + 1, baseY + 3, baseZ + 7, Blocks.stonebrick, 0, 2);
		world.setBlock(baseX + 1, baseY + 3, baseZ + 8, Blocks.stonebrick, 0, 2);
		world.setBlock(baseX + 1, baseY + 3, baseZ + 11, Blocks.stonebrick, 0, 2);
		world.setBlock(baseX + 1, baseY + 3, baseZ + 13, Blocks.stonebrick, 0, 2);
		world.setBlock(baseX + 1, baseY + 4, baseZ + 0, Blocks.stonebrick, 0, 2);
		world.setBlock(baseX + 1, baseY + 4, baseZ + 2, Blocks.stonebrick, 0, 2);
		world.setBlock(baseX + 1, baseY + 4, baseZ + 5, Blocks.stonebrick, 0, 2);
		world.setBlock(baseX + 1, baseY + 4, baseZ + 6, Blocks.stonebrick, 0, 2);
		world.setBlock(baseX + 1, baseY + 4, baseZ + 7, Blocks.stonebrick, 0, 2);
		world.setBlock(baseX + 1, baseY + 4, baseZ + 8, Blocks.stonebrick, 0, 2);
		world.setBlock(baseX + 1, baseY + 4, baseZ + 11, Blocks.stonebrick, 0, 2);
		world.setBlock(baseX + 1, baseY + 4, baseZ + 13, Blocks.stonebrick, 0, 2);
		world.setBlock(baseX + 1, baseY + 5, baseZ + 0, Blocks.stone_brick_stairs, 2, 2);
		world.setBlock(baseX + 1, baseY + 5, baseZ + 1, Blocks.stone_brick_stairs, 7, 2);
		world.setBlock(baseX + 1, baseY + 5, baseZ + 2, Blocks.stonebrick, 0, 2);
		world.setBlock(baseX + 1, baseY + 5, baseZ + 5, Blocks.stonebrick, 0, 2);
		world.setBlock(baseX + 1, baseY + 5, baseZ + 6, Blocks.stonebrick, 0, 2);
		world.setBlock(baseX + 1, baseY + 5, baseZ + 7, Blocks.stonebrick, 0, 2);
		world.setBlock(baseX + 1, baseY + 5, baseZ + 8, Blocks.stonebrick, 0, 2);
		world.setBlock(baseX + 1, baseY + 5, baseZ + 11, Blocks.stonebrick, 0, 2);
		world.setBlock(baseX + 1, baseY + 5, baseZ + 12, Blocks.stone_brick_stairs, 6, 2);
		world.setBlock(baseX + 1, baseY + 5, baseZ + 13, Blocks.stone_brick_stairs, 3, 2);
		world.setBlock(baseX + 1, baseY + 6, baseZ + 1, Blocks.stone_brick_stairs, 2, 2);
		world.setBlock(baseX + 1, baseY + 6, baseZ + 2, Blocks.stonebrick, 0, 2);
		world.setBlock(baseX + 1, baseY + 6, baseZ + 5, Blocks.stonebrick, 0, 2);
		world.setBlock(baseX + 1, baseY + 6, baseZ + 6, Blocks.stonebrick, 0, 2);
		world.setBlock(baseX + 1, baseY + 6, baseZ + 7, Blocks.stonebrick, 0, 2);
		world.setBlock(baseX + 1, baseY + 6, baseZ + 8, Blocks.stonebrick, 0, 2);
		world.setBlock(baseX + 1, baseY + 6, baseZ + 11, Blocks.stonebrick, 0, 2);
		world.setBlock(baseX + 1, baseY + 6, baseZ + 12, Blocks.stone_brick_stairs, 3, 2);
		world.setBlock(baseX + 1, baseY + 7, baseZ + 2, Blocks.stonebrick, 0, 2);
		world.setBlock(baseX + 1, baseY + 7, baseZ + 3, Blocks.stone_brick_stairs, 7, 2);
		world.setBlock(baseX + 1, baseY + 7, baseZ + 4, Blocks.stone_brick_stairs, 6, 2);
		world.setBlock(baseX + 1, baseY + 7, baseZ + 5, Blocks.stonebrick, 0, 2);
		world.setBlock(baseX + 1, baseY + 7, baseZ + 6, Blocks.stonebrick, 0, 2);
		world.setBlock(baseX + 1, baseY + 7, baseZ + 7, Blocks.stonebrick, 0, 2);
		world.setBlock(baseX + 1, baseY + 7, baseZ + 8, Blocks.stonebrick, 0, 2);
		world.setBlock(baseX + 1, baseY + 7, baseZ + 9, Blocks.stone_brick_stairs, 7, 2);
		world.setBlock(baseX + 1, baseY + 7, baseZ + 10, Blocks.stone_brick_stairs, 6, 2);
		world.setBlock(baseX + 1, baseY + 7, baseZ + 11, Blocks.stonebrick, 0, 2);
		world.setBlock(baseX + 1, baseY + 8, baseZ + 2, Blocks.stonebrick, 0, 2);
		world.setBlock(baseX + 1, baseY + 8, baseZ + 3, Blocks.stonebrick, 0, 2);
		world.setBlock(baseX + 1, baseY + 8, baseZ + 4, Blocks.stonebrick, 0, 2);
		world.setBlock(baseX + 1, baseY + 8, baseZ + 5, Blocks.stonebrick, 0, 2);
		world.setBlock(baseX + 1, baseY + 8, baseZ + 6, Blocks.stonebrick, 0, 2);
		world.setBlock(baseX + 1, baseY + 8, baseZ + 7, Blocks.stonebrick, 0, 2);
		world.setBlock(baseX + 1, baseY + 8, baseZ + 8, Blocks.stonebrick, 0, 2);
		world.setBlock(baseX + 1, baseY + 8, baseZ + 9, Blocks.stonebrick, 0, 2);
		world.setBlock(baseX + 1, baseY + 8, baseZ + 10, Blocks.stonebrick, 0, 2);
		world.setBlock(baseX + 1, baseY + 8, baseZ + 11, Blocks.stonebrick, 0, 2);
		world.setBlock(baseX + 1, baseY + 9, baseZ + 2, Blocks.stonebrick, 0, 2);
		world.setBlock(baseX + 1, baseY + 9, baseZ + 3, Blocks.stonebrick, 0, 2);
		world.setBlock(baseX + 1, baseY + 9, baseZ + 4, Blocks.stonebrick, 0, 2);
		world.setBlock(baseX + 1, baseY + 9, baseZ + 5, Blocks.stonebrick, 0, 2);
		world.setBlock(baseX + 1, baseY + 9, baseZ + 6, Blocks.stonebrick, 0, 2);
		world.setBlock(baseX + 1, baseY + 9, baseZ + 7, Blocks.stonebrick, 0, 2);
		world.setBlock(baseX + 1, baseY + 9, baseZ + 8, Blocks.stonebrick, 0, 2);
		world.setBlock(baseX + 1, baseY + 9, baseZ + 9, Blocks.stonebrick, 0, 2);
		world.setBlock(baseX + 1, baseY + 9, baseZ + 10, Blocks.stonebrick, 0, 2);
		world.setBlock(baseX + 1, baseY + 9, baseZ + 11, Blocks.stonebrick, 0, 2);
		world.setBlock(baseX + 1, baseY + 10, baseZ + 2, Blocks.stone_brick_stairs, 2, 2);
		world.setBlock(baseX + 1, baseY + 10, baseZ + 3, Blocks.stonebrick, 0, 2);
		world.setBlock(baseX + 1, baseY + 10, baseZ + 4, Blocks.stonebrick, 0, 2);
		world.setBlock(baseX + 1, baseY + 10, baseZ + 5, Blocks.stonebrick, 0, 2);
		world.setBlock(baseX + 1, baseY + 10, baseZ + 6, Blocks.stonebrick, 0, 2);
		world.setBlock(baseX + 1, baseY + 10, baseZ + 7, Blocks.stonebrick, 0, 2);
		world.setBlock(baseX + 1, baseY + 10, baseZ + 8, Blocks.stonebrick, 0, 2);
		world.setBlock(baseX + 1, baseY + 10, baseZ + 9, Blocks.stonebrick, 0, 2);
		world.setBlock(baseX + 1, baseY + 10, baseZ + 10, Blocks.stonebrick, 0, 2);
		world.setBlock(baseX + 1, baseY + 10, baseZ + 11, Blocks.stone_brick_stairs, 3, 2);
		world.setBlock(baseX + 1, baseY + 11, baseZ + 3, Blocks.stone_brick_stairs, 2, 2);
		world.setBlock(baseX + 1, baseY + 11, baseZ + 4, Blocks.stonebrick, 0, 2);
		world.setBlock(baseX + 1, baseY + 11, baseZ + 5, Blocks.stonebrick, 0, 2);
		world.setBlock(baseX + 1, baseY + 11, baseZ + 6, Blocks.stone_brick_stairs, 3, 2);
		world.setBlock(baseX + 1, baseY + 11, baseZ + 7, Blocks.stone_brick_stairs, 2, 2);
		world.setBlock(baseX + 1, baseY + 11, baseZ + 8, Blocks.stonebrick, 0, 2);
		world.setBlock(baseX + 1, baseY + 11, baseZ + 9, Blocks.stonebrick, 0, 2);
		world.setBlock(baseX + 1, baseY + 11, baseZ + 10, Blocks.stone_brick_stairs, 3, 2);
		world.setBlock(baseX + 1, baseY + 12, baseZ + 4, Blocks.stone_brick_stairs, 2, 2);
		world.setBlock(baseX + 1, baseY + 12, baseZ + 5, Blocks.stonebrick, 0, 2);
		world.setBlock(baseX + 1, baseY + 12, baseZ + 8, Blocks.stonebrick, 0, 2);
		world.setBlock(baseX + 1, baseY + 12, baseZ + 9, Blocks.stone_brick_stairs, 3, 2);
		world.setBlock(baseX + 1, baseY + 13, baseZ + 5, Blocks.stone_brick_stairs, 2, 2);
		world.setBlock(baseX + 1, baseY + 13, baseZ + 6, Blocks.stone_brick_stairs, 7, 2);
		world.setBlock(baseX + 1, baseY + 13, baseZ + 7, Blocks.stone_brick_stairs, 6, 2);
		world.setBlock(baseX + 1, baseY + 13, baseZ + 8, Blocks.stone_brick_stairs, 3, 2);
		world.setBlock(baseX + 2, baseY + 1, baseZ + 2, Blocks.stonebrick, 0, 2);
		world.setBlock(baseX + 2, baseY + 1, baseZ + 11, Blocks.stonebrick, 0, 2);
		world.setBlock(baseX + 2, baseY + 2, baseZ + 2, Blocks.stonebrick, 0, 2);
		world.setBlock(baseX + 2, baseY + 2, baseZ + 11, Blocks.stonebrick, 0, 2);
		world.setBlock(baseX + 2, baseY + 8, baseZ + 2, Blocks.stone_brick_stairs, 5, 2);
		world.setBlock(baseX + 2, baseY + 8, baseZ + 11, Blocks.stone_brick_stairs, 5, 2);
		world.setBlock(baseX + 2, baseY + 9, baseZ + 2, Blocks.stonebrick, 0, 2);
		world.setBlock(baseX + 2, baseY + 9, baseZ + 11, Blocks.stonebrick, 0, 2);
		world.setBlock(baseX + 2, baseY + 10, baseZ + 2, Blocks.spruce_stairs, 2, 2);
		world.setBlock(baseX + 2, baseY + 10, baseZ + 3, Blocks.spruce_stairs, 7, 2);
		world.setBlock(baseX + 2, baseY + 10, baseZ + 10, Blocks.spruce_stairs, 6, 2);
		world.setBlock(baseX + 2, baseY + 10, baseZ + 11, Blocks.spruce_stairs, 3, 2);
		world.setBlock(baseX + 2, baseY + 11, baseZ + 3, Blocks.spruce_stairs, 2, 2);
		world.setBlock(baseX + 2, baseY + 11, baseZ + 4, Blocks.spruce_stairs, 7, 2);
		world.setBlock(baseX + 2, baseY + 11, baseZ + 9, Blocks.spruce_stairs, 6, 2);
		world.setBlock(baseX + 2, baseY + 11, baseZ + 10, Blocks.spruce_stairs, 3, 2);
		world.setBlock(baseX + 2, baseY + 12, baseZ + 4, Blocks.spruce_stairs, 2, 2);
		world.setBlock(baseX + 2, baseY + 12, baseZ + 5, Blocks.spruce_stairs, 7, 2);
		world.setBlock(baseX + 2, baseY + 12, baseZ + 8, Blocks.spruce_stairs, 6, 2);
		world.setBlock(baseX + 2, baseY + 12, baseZ + 9, Blocks.spruce_stairs, 3, 2);
		world.setBlock(baseX + 2, baseY + 13, baseZ + 5, Blocks.spruce_stairs, 2, 2);
		world.setBlock(baseX + 2, baseY + 13, baseZ + 6, Blocks.spruce_stairs, 7, 2);
		world.setBlock(baseX + 2, baseY + 13, baseZ + 7, Blocks.spruce_stairs, 6, 2);
		world.setBlock(baseX + 2, baseY + 13, baseZ + 8, Blocks.spruce_stairs, 3, 2);
		world.setBlock(baseX + 3, baseY + 1, baseZ + 2, Blocks.stonebrick, 0, 2);
		world.setBlock(baseX + 3, baseY + 1, baseZ + 11, Blocks.stonebrick, 0, 2);
		world.setBlock(baseX + 3, baseY + 2, baseZ + 2, Blocks.stonebrick, 0, 2);
		world.setBlock(baseX + 3, baseY + 2, baseZ + 11, Blocks.stonebrick, 0, 2);
		world.setBlock(baseX + 3, baseY + 9, baseZ + 2, Blocks.stonebrick, 0, 2);
		world.setBlock(baseX + 3, baseY + 9, baseZ + 11, Blocks.stonebrick, 0, 2);
		world.setBlock(baseX + 3, baseY + 10, baseZ + 2, Blocks.spruce_stairs, 2, 2);
		world.setBlock(baseX + 3, baseY + 10, baseZ + 3, Blocks.spruce_stairs, 7, 2);
		world.setBlock(baseX + 3, baseY + 10, baseZ + 10, Blocks.spruce_stairs, 6, 2);
		world.setBlock(baseX + 3, baseY + 10, baseZ + 11, Blocks.spruce_stairs, 3, 2);
		world.setBlock(baseX + 3, baseY + 11, baseZ + 3, Blocks.spruce_stairs, 2, 2);
		world.setBlock(baseX + 3, baseY + 11, baseZ + 4, Blocks.spruce_stairs, 7, 2);
		world.setBlock(baseX + 3, baseY + 11, baseZ + 9, Blocks.spruce_stairs, 6, 2);
		world.setBlock(baseX + 3, baseY + 11, baseZ + 10, Blocks.spruce_stairs, 3, 2);
		world.setBlock(baseX + 3, baseY + 12, baseZ + 4, Blocks.spruce_stairs, 2, 2);
		world.setBlock(baseX + 3, baseY + 12, baseZ + 5, Blocks.spruce_stairs, 7, 2);
		world.setBlock(baseX + 3, baseY + 12, baseZ + 8, Blocks.spruce_stairs, 6, 2);
		world.setBlock(baseX + 3, baseY + 12, baseZ + 9, Blocks.spruce_stairs, 3, 2);
		world.setBlock(baseX + 3, baseY + 13, baseZ + 5, Blocks.spruce_stairs, 2, 2);
		world.setBlock(baseX + 3, baseY + 13, baseZ + 6, Blocks.spruce_stairs, 7, 2);
		world.setBlock(baseX + 3, baseY + 13, baseZ + 7, Blocks.spruce_stairs, 6, 2);
		world.setBlock(baseX + 3, baseY + 13, baseZ + 8, Blocks.spruce_stairs, 3, 2);
		world.setBlock(baseX + 4, baseY + 1, baseZ + 2, Blocks.stonebrick, 0, 2);
		world.setBlock(baseX + 4, baseY + 1, baseZ + 11, Blocks.stonebrick, 0, 2);
		world.setBlock(baseX + 4, baseY + 2, baseZ + 2, Blocks.stonebrick, 0, 2);
		world.setBlock(baseX + 4, baseY + 2, baseZ + 11, Blocks.stonebrick, 0, 2);
		world.setBlock(baseX + 4, baseY + 8, baseZ + 2, Blocks.stone_brick_stairs, 4, 2);
		world.setBlock(baseX + 4, baseY + 8, baseZ + 11, Blocks.stone_brick_stairs, 4, 2);
		world.setBlock(baseX + 4, baseY + 9, baseZ + 2, Blocks.stonebrick, 0, 2);
		world.setBlock(baseX + 4, baseY + 9, baseZ + 11, Blocks.stonebrick, 0, 2);
		world.setBlock(baseX + 4, baseY + 10, baseZ + 2, Blocks.spruce_stairs, 2, 2);
		world.setBlock(baseX + 4, baseY + 10, baseZ + 3, Blocks.spruce_stairs, 7, 2);
		world.setBlock(baseX + 4, baseY + 10, baseZ + 10, Blocks.spruce_stairs, 6, 2);
		world.setBlock(baseX + 4, baseY + 10, baseZ + 11, Blocks.spruce_stairs, 3, 2);
		world.setBlock(baseX + 4, baseY + 11, baseZ + 3, Blocks.spruce_stairs, 2, 2);
		world.setBlock(baseX + 4, baseY + 11, baseZ + 4, Blocks.spruce_stairs, 7, 2);
		world.setBlock(baseX + 4, baseY + 11, baseZ + 9, Blocks.spruce_stairs, 6, 2);
		world.setBlock(baseX + 4, baseY + 11, baseZ + 10, Blocks.spruce_stairs, 3, 2);
		world.setBlock(baseX + 4, baseY + 12, baseZ + 4, Blocks.spruce_stairs, 2, 2);
		world.setBlock(baseX + 4, baseY + 12, baseZ + 5, Blocks.spruce_stairs, 7, 2);
		world.setBlock(baseX + 4, baseY + 12, baseZ + 8, Blocks.spruce_stairs, 6, 2);
		world.setBlock(baseX + 4, baseY + 12, baseZ + 9, Blocks.spruce_stairs, 3, 2);
		world.setBlock(baseX + 4, baseY + 13, baseZ + 5, Blocks.spruce_stairs, 2, 2);
		world.setBlock(baseX + 4, baseY + 13, baseZ + 6, Blocks.spruce_stairs, 7, 2);
		world.setBlock(baseX + 4, baseY + 13, baseZ + 7, Blocks.spruce_stairs, 6, 2);
		world.setBlock(baseX + 5, baseY + 1, baseZ + 0, Blocks.stonebrick, 0, 2);
		world.setBlock(baseX + 5, baseY + 1, baseZ + 2, Blocks.stonebrick, 0, 2);
		world.setBlock(baseX + 5, baseY + 1, baseZ + 11, Blocks.stonebrick, 0, 2);
		world.setBlock(baseX + 5, baseY + 1, baseZ + 13, Blocks.stonebrick, 0, 2);
		world.setBlock(baseX + 5, baseY + 2, baseZ + 0, Blocks.stonebrick, 0, 2);
		world.setBlock(baseX + 5, baseY + 2, baseZ + 2, Blocks.stonebrick, 0, 2);
		world.setBlock(baseX + 5, baseY + 2, baseZ + 11, Blocks.stonebrick, 0, 2);
		world.setBlock(baseX + 5, baseY + 2, baseZ + 13, Blocks.stonebrick, 0, 2);
		world.setBlock(baseX + 5, baseY + 3, baseZ + 0, Blocks.stonebrick, 0, 2);
		world.setBlock(baseX + 5, baseY + 3, baseZ + 2, Blocks.stonebrick, 0, 2);
		world.setBlock(baseX + 5, baseY + 3, baseZ + 11, Blocks.stonebrick, 0, 2);
		world.setBlock(baseX + 5, baseY + 3, baseZ + 13, Blocks.stonebrick, 0, 2);
		world.setBlock(baseX + 5, baseY + 4, baseZ + 0, Blocks.stonebrick, 0, 2);
		world.setBlock(baseX + 5, baseY + 4, baseZ + 2, Blocks.stonebrick, 0, 2);
		world.setBlock(baseX + 5, baseY + 4, baseZ + 11, Blocks.stonebrick, 0, 2);
		world.setBlock(baseX + 5, baseY + 4, baseZ + 13, Blocks.stonebrick, 0, 2);
		world.setBlock(baseX + 5, baseY + 5, baseZ + 0, Blocks.stone_brick_stairs, 2, 2);
		world.setBlock(baseX + 5, baseY + 5, baseZ + 1, Blocks.stone_brick_stairs, 7, 2);
		world.setBlock(baseX + 5, baseY + 5, baseZ + 2, Blocks.stonebrick, 0, 2);
		world.setBlock(baseX + 5, baseY + 5, baseZ + 11, Blocks.stonebrick, 0, 2);
		world.setBlock(baseX + 5, baseY + 5, baseZ + 12, Blocks.stone_brick_stairs, 6, 2);
		world.setBlock(baseX + 5, baseY + 5, baseZ + 13, Blocks.stone_brick_stairs, 3, 2);
		world.setBlock(baseX + 5, baseY + 6, baseZ + 1, Blocks.stone_brick_stairs, 2, 2);
		world.setBlock(baseX + 5, baseY + 6, baseZ + 2, Blocks.stonebrick, 0, 2);
		world.setBlock(baseX + 5, baseY + 6, baseZ + 11, Blocks.stonebrick, 0, 2);
		world.setBlock(baseX + 5, baseY + 6, baseZ + 12, Blocks.stone_brick_stairs, 3, 2);
		world.setBlock(baseX + 5, baseY + 7, baseZ + 2, Blocks.stonebrick, 0, 2);
		world.setBlock(baseX + 5, baseY + 7, baseZ + 11, Blocks.stonebrick, 0, 2);
		world.setBlock(baseX + 5, baseY + 8, baseZ + 2, Blocks.stonebrick, 0, 2);
		world.setBlock(baseX + 5, baseY + 8, baseZ + 11, Blocks.stonebrick, 0, 2);
		world.setBlock(baseX + 5, baseY + 9, baseZ + 2, Blocks.stonebrick, 0, 2);
		world.setBlock(baseX + 5, baseY + 9, baseZ + 11, Blocks.stonebrick, 0, 2);
		world.setBlock(baseX + 5, baseY + 10, baseZ + 2, Blocks.stone_brick_stairs, 2, 2);
		world.setBlock(baseX + 5, baseY + 10, baseZ + 3, Blocks.stone_brick_stairs, 7, 2);
		world.setBlock(baseX + 5, baseY + 10, baseZ + 10, Blocks.stone_brick_stairs, 6, 2);
		world.setBlock(baseX + 5, baseY + 10, baseZ + 11, Blocks.stone_brick_stairs, 3, 2);
		world.setBlock(baseX + 5, baseY + 11, baseZ + 3, Blocks.stone_brick_stairs, 2, 2);
		world.setBlock(baseX + 5, baseY + 11, baseZ + 4, Blocks.stone_brick_stairs, 7, 2);
		world.setBlock(baseX + 5, baseY + 11, baseZ + 9, Blocks.stone_brick_stairs, 6, 2);
		world.setBlock(baseX + 5, baseY + 11, baseZ + 10, Blocks.stone_brick_stairs, 3, 2);
		world.setBlock(baseX + 5, baseY + 12, baseZ + 4, Blocks.stone_brick_stairs, 2, 2);
		world.setBlock(baseX + 5, baseY + 12, baseZ + 5, Blocks.stone_brick_stairs, 7, 2);
		world.setBlock(baseX + 5, baseY + 12, baseZ + 8, Blocks.stone_brick_stairs, 6, 2);
		world.setBlock(baseX + 5, baseY + 12, baseZ + 9, Blocks.stone_brick_stairs, 3, 2);
		world.setBlock(baseX + 5, baseY + 13, baseZ + 5, Blocks.stone_brick_stairs, 2, 2);
		world.setBlock(baseX + 5, baseY + 13, baseZ + 6, Blocks.stone_brick_stairs, 7, 2);
		world.setBlock(baseX + 5, baseY + 13, baseZ + 7, Blocks.stone_brick_stairs, 6, 2);
		world.setBlock(baseX + 5, baseY + 13, baseZ + 8, Blocks.stone_brick_stairs, 3, 2);
		world.setBlock(baseX + 6, baseY + 1, baseZ + 2, Blocks.stonebrick, 0, 2);
		world.setBlock(baseX + 6, baseY + 1, baseZ + 11, Blocks.stonebrick, 0, 2);
		world.setBlock(baseX + 6, baseY + 2, baseZ + 2, Blocks.stonebrick, 0, 2);
		world.setBlock(baseX + 6, baseY + 2, baseZ + 11, Blocks.stonebrick, 0, 2);
		world.setBlock(baseX + 6, baseY + 8, baseZ + 2, Blocks.stone_brick_stairs, 5, 2);
		world.setBlock(baseX + 6, baseY + 8, baseZ + 11, Blocks.stone_brick_stairs, 5, 2);
		world.setBlock(baseX + 6, baseY + 9, baseZ + 2, Blocks.stonebrick, 0, 2);
		world.setBlock(baseX + 6, baseY + 9, baseZ + 11, Blocks.stonebrick, 0, 2);
		world.setBlock(baseX + 6, baseY + 10, baseZ + 2, Blocks.spruce_stairs, 2, 2);
		world.setBlock(baseX + 6, baseY + 10, baseZ + 3, Blocks.spruce_stairs, 7, 2);
		world.setBlock(baseX + 6, baseY + 10, baseZ + 10, Blocks.spruce_stairs, 6, 2);
		world.setBlock(baseX + 6, baseY + 10, baseZ + 11, Blocks.spruce_stairs, 3, 2);
		world.setBlock(baseX + 6, baseY + 11, baseZ + 3, Blocks.spruce_stairs, 2, 2);
		world.setBlock(baseX + 6, baseY + 11, baseZ + 4, Blocks.spruce_stairs, 7, 2);
		world.setBlock(baseX + 6, baseY + 11, baseZ + 9, Blocks.spruce_stairs, 6, 2);
		world.setBlock(baseX + 6, baseY + 11, baseZ + 10, Blocks.spruce_stairs, 3, 2);
		world.setBlock(baseX + 6, baseY + 12, baseZ + 4, Blocks.spruce_stairs, 2, 2);
		world.setBlock(baseX + 6, baseY + 12, baseZ + 5, Blocks.spruce_stairs, 7, 2);
		world.setBlock(baseX + 6, baseY + 12, baseZ + 8, Blocks.spruce_stairs, 6, 2);
		world.setBlock(baseX + 6, baseY + 12, baseZ + 9, Blocks.spruce_stairs, 3, 2);
		world.setBlock(baseX + 6, baseY + 13, baseZ + 5, Blocks.spruce_stairs, 2, 2);
		world.setBlock(baseX + 6, baseY + 13, baseZ + 6, Blocks.spruce_stairs, 7, 2);
		world.setBlock(baseX + 6, baseY + 13, baseZ + 7, Blocks.spruce_stairs, 6, 2);
		world.setBlock(baseX + 6, baseY + 13, baseZ + 8, Blocks.spruce_stairs, 3, 2);
		world.setBlock(baseX + 7, baseY + 0, baseZ + 0, Blocks.cobblestone, 0, 2);
		world.setBlock(baseX + 7, baseY + 0, baseZ + 1, Blocks.cobblestone, 0, 2);
		world.setBlock(baseX + 7, baseY + 0, baseZ + 2, Blocks.cobblestone, 0, 2);
		world.setBlock(baseX + 7, baseY + 0, baseZ + 3, Blocks.cobblestone, 0, 2);
		world.setBlock(baseX + 7, baseY + 0, baseZ + 4, Blocks.cobblestone, 0, 2);
		world.setBlock(baseX + 7, baseY + 0, baseZ + 5, Blocks.cobblestone, 0, 2);
		world.setBlock(baseX + 7, baseY + 0, baseZ + 6, Blocks.cobblestone, 0, 2);
		world.setBlock(baseX + 7, baseY + 0, baseZ + 7, Blocks.cobblestone, 0, 2);
		world.setBlock(baseX + 7, baseY + 0, baseZ + 8, Blocks.cobblestone, 0, 2);
		world.setBlock(baseX + 7, baseY + 0, baseZ + 9, Blocks.cobblestone, 0, 2);
		world.setBlock(baseX + 7, baseY + 0, baseZ + 10, Blocks.cobblestone, 0, 2);
		world.setBlock(baseX + 7, baseY + 0, baseZ + 11, Blocks.cobblestone, 0, 2);
		world.setBlock(baseX + 7, baseY + 0, baseZ + 12, Blocks.cobblestone, 0, 2);
		world.setBlock(baseX + 7, baseY + 0, baseZ + 13, Blocks.cobblestone, 0, 2);
		world.setBlock(baseX + 7, baseY + 1, baseZ + 2, Blocks.stonebrick, 0, 2);
		world.setBlock(baseX + 7, baseY + 1, baseZ + 11, Blocks.stonebrick, 0, 2);
		world.setBlock(baseX + 7, baseY + 2, baseZ + 2, Blocks.stonebrick, 0, 2);
		world.setBlock(baseX + 7, baseY + 2, baseZ + 11, Blocks.stonebrick, 0, 2);
		world.setBlock(baseX + 7, baseY + 9, baseZ + 2, Blocks.stonebrick, 0, 2);
		world.setBlock(baseX + 7, baseY + 9, baseZ + 11, Blocks.stonebrick, 0, 2);
		world.setBlock(baseX + 7, baseY + 10, baseZ + 2, Blocks.spruce_stairs, 2, 2);
		world.setBlock(baseX + 7, baseY + 10, baseZ + 3, Blocks.spruce_stairs, 7, 2);
		world.setBlock(baseX + 7, baseY + 10, baseZ + 10, Blocks.spruce_stairs, 6, 2);
		world.setBlock(baseX + 7, baseY + 10, baseZ + 11, Blocks.spruce_stairs, 3, 2);
		world.setBlock(baseX + 7, baseY + 11, baseZ + 3, Blocks.spruce_stairs, 2, 2);
		world.setBlock(baseX + 7, baseY + 11, baseZ + 4, Blocks.spruce_stairs, 7, 2);
		world.setBlock(baseX + 7, baseY + 11, baseZ + 9, Blocks.spruce_stairs, 6, 2);
		world.setBlock(baseX + 7, baseY + 11, baseZ + 10, Blocks.spruce_stairs, 3, 2);
		world.setBlock(baseX + 7, baseY + 12, baseZ + 4, Blocks.spruce_stairs, 2, 2);
		world.setBlock(baseX + 7, baseY + 12, baseZ + 5, Blocks.spruce_stairs, 7, 2);
		world.setBlock(baseX + 7, baseY + 12, baseZ + 8, Blocks.spruce_stairs, 6, 2);
		world.setBlock(baseX + 7, baseY + 12, baseZ + 9, Blocks.spruce_stairs, 3, 2);
		world.setBlock(baseX + 7, baseY + 13, baseZ + 5, Blocks.spruce_stairs, 2, 2);
		world.setBlock(baseX + 7, baseY + 13, baseZ + 6, Blocks.spruce_stairs, 7, 2);
		world.setBlock(baseX + 7, baseY + 13, baseZ + 7, Blocks.spruce_stairs, 6, 2);
		world.setBlock(baseX + 7, baseY + 13, baseZ + 8, Blocks.spruce_stairs, 3, 2);
		world.setBlock(baseX + 8, baseY + 1, baseZ + 2, Blocks.stonebrick, 0, 2);
		world.setBlock(baseX + 8, baseY + 1, baseZ + 11, Blocks.stonebrick, 0, 2);
		world.setBlock(baseX + 8, baseY + 2, baseZ + 2, Blocks.stonebrick, 0, 2);
		world.setBlock(baseX + 8, baseY + 2, baseZ + 11, Blocks.stonebrick, 0, 2);
		world.setBlock(baseX + 8, baseY + 8, baseZ + 2, Blocks.stone_brick_stairs, 4, 2);
		world.setBlock(baseX + 8, baseY + 8, baseZ + 11, Blocks.stone_brick_stairs, 4, 2);
		world.setBlock(baseX + 8, baseY + 9, baseZ + 2, Blocks.stonebrick, 0, 2);
		world.setBlock(baseX + 8, baseY + 9, baseZ + 11, Blocks.stonebrick, 0, 2);
		world.setBlock(baseX + 8, baseY + 10, baseZ + 2, Blocks.spruce_stairs, 2, 2);
		world.setBlock(baseX + 8, baseY + 10, baseZ + 3, Blocks.spruce_stairs, 7, 2);
		world.setBlock(baseX + 8, baseY + 10, baseZ + 10, Blocks.spruce_stairs, 6, 2);
		world.setBlock(baseX + 8, baseY + 10, baseZ + 11, Blocks.spruce_stairs, 3, 2);
		world.setBlock(baseX + 8, baseY + 11, baseZ + 3, Blocks.spruce_stairs, 2, 2);
		world.setBlock(baseX + 8, baseY + 11, baseZ + 4, Blocks.spruce_stairs, 7, 2);
		world.setBlock(baseX + 8, baseY + 11, baseZ + 9, Blocks.spruce_stairs, 6, 2);
		world.setBlock(baseX + 8, baseY + 11, baseZ + 10, Blocks.spruce_stairs, 3, 2);
		world.setBlock(baseX + 8, baseY + 12, baseZ + 4, Blocks.spruce_stairs, 2, 2);
		world.setBlock(baseX + 8, baseY + 12, baseZ + 5, Blocks.spruce_stairs, 7, 2);
		world.setBlock(baseX + 8, baseY + 12, baseZ + 8, Blocks.spruce_stairs, 6, 2);
		world.setBlock(baseX + 8, baseY + 12, baseZ + 9, Blocks.spruce_stairs, 3, 2);
		world.setBlock(baseX + 8, baseY + 13, baseZ + 5, Blocks.spruce_stairs, 2, 2);
		world.setBlock(baseX + 8, baseY + 13, baseZ + 6, Blocks.spruce_stairs, 7, 2);
		world.setBlock(baseX + 8, baseY + 13, baseZ + 7, Blocks.spruce_stairs, 6, 2);
		world.setBlock(baseX + 8, baseY + 13, baseZ + 8, Blocks.spruce_stairs, 3, 2);
		world.setBlock(baseX + 9, baseY + 1, baseZ + 0, Blocks.stonebrick, 0, 2);
		world.setBlock(baseX + 9, baseY + 1, baseZ + 2, Blocks.stonebrick, 0, 2);
		world.setBlock(baseX + 9, baseY + 1, baseZ + 11, Blocks.stonebrick, 0, 2);
		world.setBlock(baseX + 9, baseY + 1, baseZ + 13, Blocks.stonebrick, 0, 2);
		world.setBlock(baseX + 9, baseY + 2, baseZ + 0, Blocks.stonebrick, 0, 2);
		world.setBlock(baseX + 9, baseY + 2, baseZ + 2, Blocks.stonebrick, 0, 2);
		world.setBlock(baseX + 9, baseY + 2, baseZ + 11, Blocks.stonebrick, 0, 2);
		world.setBlock(baseX + 9, baseY + 2, baseZ + 13, Blocks.stonebrick, 0, 2);
		world.setBlock(baseX + 9, baseY + 3, baseZ + 0, Blocks.stonebrick, 0, 2);
		world.setBlock(baseX + 9, baseY + 3, baseZ + 2, Blocks.stonebrick, 0, 2);
		world.setBlock(baseX + 9, baseY + 3, baseZ + 11, Blocks.stonebrick, 0, 2);
		world.setBlock(baseX + 9, baseY + 3, baseZ + 13, Blocks.stonebrick, 0, 2);
		world.setBlock(baseX + 9, baseY + 4, baseZ + 0, Blocks.stonebrick, 0, 2);
		world.setBlock(baseX + 9, baseY + 4, baseZ + 2, Blocks.stonebrick, 0, 2);
		world.setBlock(baseX + 9, baseY + 4, baseZ + 11, Blocks.stonebrick, 0, 2);
		world.setBlock(baseX + 9, baseY + 4, baseZ + 13, Blocks.stonebrick, 0, 2);
		world.setBlock(baseX + 9, baseY + 5, baseZ + 0, Blocks.stone_brick_stairs, 2, 2);
		world.setBlock(baseX + 9, baseY + 5, baseZ + 1, Blocks.stone_brick_stairs, 7, 2);
		world.setBlock(baseX + 9, baseY + 5, baseZ + 2, Blocks.stonebrick, 0, 2);
		world.setBlock(baseX + 9, baseY + 5, baseZ + 11, Blocks.stonebrick, 0, 2);
		world.setBlock(baseX + 9, baseY + 5, baseZ + 12, Blocks.stone_brick_stairs, 6, 2);
		world.setBlock(baseX + 9, baseY + 5, baseZ + 13, Blocks.stone_brick_stairs, 3, 2);
		world.setBlock(baseX + 9, baseY + 6, baseZ + 1, Blocks.stone_brick_stairs, 2, 2);
		world.setBlock(baseX + 9, baseY + 6, baseZ + 2, Blocks.stonebrick, 0, 2);
		world.setBlock(baseX + 9, baseY + 6, baseZ + 11, Blocks.stonebrick, 0, 2);
		world.setBlock(baseX + 9, baseY + 6, baseZ + 12, Blocks.stone_brick_stairs, 3, 2);
		world.setBlock(baseX + 9, baseY + 7, baseZ + 2, Blocks.stonebrick, 0, 2);
		world.setBlock(baseX + 9, baseY + 7, baseZ + 11, Blocks.stonebrick, 0, 2);
		world.setBlock(baseX + 9, baseY + 8, baseZ + 2, Blocks.stonebrick, 0, 2);
		world.setBlock(baseX + 9, baseY + 8, baseZ + 11, Blocks.stonebrick, 0, 2);
		world.setBlock(baseX + 9, baseY + 9, baseZ + 2, Blocks.stonebrick, 0, 2);
		world.setBlock(baseX + 9, baseY + 9, baseZ + 11, Blocks.stonebrick, 0, 2);
		world.setBlock(baseX + 9, baseY + 10, baseZ + 2, Blocks.stone_brick_stairs, 2, 2);
		world.setBlock(baseX + 9, baseY + 10, baseZ + 3, Blocks.stone_brick_stairs, 7, 2);
		world.setBlock(baseX + 9, baseY + 10, baseZ + 10, Blocks.stone_brick_stairs, 6, 2);
		world.setBlock(baseX + 9, baseY + 10, baseZ + 11, Blocks.stone_brick_stairs, 3, 2);
		world.setBlock(baseX + 9, baseY + 11, baseZ + 3, Blocks.stone_brick_stairs, 2, 2);
		world.setBlock(baseX + 9, baseY + 11, baseZ + 4, Blocks.stone_brick_stairs, 7, 2);
		world.setBlock(baseX + 9, baseY + 11, baseZ + 9, Blocks.stone_brick_stairs, 6, 2);
		world.setBlock(baseX + 9, baseY + 11, baseZ + 10, Blocks.stone_brick_stairs, 3, 2);
		world.setBlock(baseX + 9, baseY + 12, baseZ + 4, Blocks.stone_brick_stairs, 2, 2);
		world.setBlock(baseX + 9, baseY + 12, baseZ + 5, Blocks.stone_brick_stairs, 7, 2);
		world.setBlock(baseX + 9, baseY + 12, baseZ + 8, Blocks.stone_brick_stairs, 6, 2);
		world.setBlock(baseX + 9, baseY + 12, baseZ + 9, Blocks.stone_brick_stairs, 3, 2);
		world.setBlock(baseX + 9, baseY + 13, baseZ + 5, Blocks.stone_brick_stairs, 2, 2);
		world.setBlock(baseX + 9, baseY + 13, baseZ + 6, Blocks.stone_brick_stairs, 7, 2);
		world.setBlock(baseX + 9, baseY + 13, baseZ + 7, Blocks.stone_brick_stairs, 6, 2);
		world.setBlock(baseX + 9, baseY + 13, baseZ + 8, Blocks.stone_brick_stairs, 3, 2);
		world.setBlock(baseX + 10, baseY + 1, baseZ + 2, Blocks.stonebrick, 0, 2);
		world.setBlock(baseX + 10, baseY + 1, baseZ + 11, Blocks.stonebrick, 0, 2);
		world.setBlock(baseX + 10, baseY + 2, baseZ + 2, Blocks.stonebrick, 0, 2);
		world.setBlock(baseX + 10, baseY + 2, baseZ + 11, Blocks.stonebrick, 0, 2);
		world.setBlock(baseX + 10, baseY + 8, baseZ + 2, Blocks.stone_brick_stairs, 5, 2);
		world.setBlock(baseX + 10, baseY + 8, baseZ + 11, Blocks.stone_brick_stairs, 5, 2);
		world.setBlock(baseX + 10, baseY + 9, baseZ + 2, Blocks.stonebrick, 0, 2);
		world.setBlock(baseX + 10, baseY + 9, baseZ + 11, Blocks.stonebrick, 0, 2);
		world.setBlock(baseX + 10, baseY + 10, baseZ + 2, Blocks.spruce_stairs, 2, 2);
		world.setBlock(baseX + 10, baseY + 10, baseZ + 3, Blocks.spruce_stairs, 7, 2);
		world.setBlock(baseX + 10, baseY + 10, baseZ + 10, Blocks.spruce_stairs, 6, 2);
		world.setBlock(baseX + 10, baseY + 10, baseZ + 11, Blocks.spruce_stairs, 3, 2);
		world.setBlock(baseX + 10, baseY + 11, baseZ + 3, Blocks.spruce_stairs, 2, 2);
		world.setBlock(baseX + 10, baseY + 11, baseZ + 4, Blocks.spruce_stairs, 7, 2);
		world.setBlock(baseX + 10, baseY + 11, baseZ + 9, Blocks.spruce_stairs, 6, 2);
		world.setBlock(baseX + 10, baseY + 11, baseZ + 10, Blocks.spruce_stairs, 3, 2);
		world.setBlock(baseX + 10, baseY + 12, baseZ + 4, Blocks.spruce_stairs, 2, 2);
		world.setBlock(baseX + 10, baseY + 12, baseZ + 5, Blocks.spruce_stairs, 7, 2);
		world.setBlock(baseX + 10, baseY + 12, baseZ + 8, Blocks.spruce_stairs, 6, 2);
		world.setBlock(baseX + 10, baseY + 12, baseZ + 9, Blocks.spruce_stairs, 3, 2);
		world.setBlock(baseX + 10, baseY + 13, baseZ + 5, Blocks.spruce_stairs, 2, 2);
		world.setBlock(baseX + 10, baseY + 13, baseZ + 6, Blocks.spruce_stairs, 7, 2);
		world.setBlock(baseX + 10, baseY + 13, baseZ + 7, Blocks.spruce_stairs, 6, 2);
		world.setBlock(baseX + 10, baseY + 13, baseZ + 8, Blocks.spruce_stairs, 3, 2);
		world.setBlock(baseX + 11, baseY + 1, baseZ + 2, Blocks.stonebrick, 0, 2);
		world.setBlock(baseX + 11, baseY + 1, baseZ + 11, Blocks.stonebrick, 0, 2);
		world.setBlock(baseX + 11, baseY + 2, baseZ + 2, Blocks.stonebrick, 0, 2);
		world.setBlock(baseX + 11, baseY + 2, baseZ + 11, Blocks.stonebrick, 0, 2);
		world.setBlock(baseX + 11, baseY + 9, baseZ + 2, Blocks.stonebrick, 0, 2);
		world.setBlock(baseX + 11, baseY + 9, baseZ + 11, Blocks.stonebrick, 0, 2);
		world.setBlock(baseX + 11, baseY + 10, baseZ + 2, Blocks.spruce_stairs, 2, 2);
		world.setBlock(baseX + 11, baseY + 10, baseZ + 3, Blocks.spruce_stairs, 7, 2);
		world.setBlock(baseX + 11, baseY + 10, baseZ + 10, Blocks.spruce_stairs, 6, 2);
		world.setBlock(baseX + 11, baseY + 10, baseZ + 11, Blocks.spruce_stairs, 3, 2);
		world.setBlock(baseX + 11, baseY + 11, baseZ + 3, Blocks.spruce_stairs, 2, 2);
		world.setBlock(baseX + 11, baseY + 11, baseZ + 4, Blocks.spruce_stairs, 7, 2);
		world.setBlock(baseX + 11, baseY + 11, baseZ + 9, Blocks.spruce_stairs, 6, 2);
		world.setBlock(baseX + 11, baseY + 11, baseZ + 10, Blocks.spruce_stairs, 3, 2);
		world.setBlock(baseX + 11, baseY + 12, baseZ + 4, Blocks.spruce_stairs, 2, 2);
		world.setBlock(baseX + 11, baseY + 12, baseZ + 5, Blocks.spruce_stairs, 7, 2);
		world.setBlock(baseX + 11, baseY + 12, baseZ + 8, Blocks.spruce_stairs, 6, 2);
		world.setBlock(baseX + 11, baseY + 12, baseZ + 9, Blocks.spruce_stairs, 3, 2);
		world.setBlock(baseX + 11, baseY + 13, baseZ + 5, Blocks.spruce_stairs, 2, 2);
		world.setBlock(baseX + 11, baseY + 13, baseZ + 6, Blocks.spruce_stairs, 7, 2);
		world.setBlock(baseX + 11, baseY + 13, baseZ + 7, Blocks.spruce_stairs, 6, 2);
		world.setBlock(baseX + 11, baseY + 13, baseZ + 8, Blocks.spruce_stairs, 3, 2);
		world.setBlock(baseX + 12, baseY + 1, baseZ + 2, Blocks.stonebrick, 0, 2);
		world.setBlock(baseX + 12, baseY + 1, baseZ + 5, Blocks.stonebrick, 0, 2);
		world.setBlock(baseX + 12, baseY + 1, baseZ + 8, Blocks.stonebrick, 0, 2);
		world.setBlock(baseX + 12, baseY + 1, baseZ + 11, Blocks.stonebrick, 0, 2);
		world.setBlock(baseX + 12, baseY + 2, baseZ + 2, Blocks.stonebrick, 0, 2);
		world.setBlock(baseX + 12, baseY + 2, baseZ + 5, Blocks.stonebrick, 0, 2);
		world.setBlock(baseX + 12, baseY + 2, baseZ + 8, Blocks.stonebrick, 0, 2);
		world.setBlock(baseX + 12, baseY + 2, baseZ + 11, Blocks.stonebrick, 0, 2);
		world.setBlock(baseX + 12, baseY + 3, baseZ + 5, Blocks.stonebrick, 0, 2);
		world.setBlock(baseX + 12, baseY + 3, baseZ + 8, Blocks.stonebrick, 0, 2);
		world.setBlock(baseX + 12, baseY + 4, baseZ + 5, Blocks.stonebrick, 0, 2);
		world.setBlock(baseX + 12, baseY + 4, baseZ + 8, Blocks.stonebrick, 0, 2);
		world.setBlock(baseX + 12, baseY + 5, baseZ + 5, Blocks.stonebrick, 0, 2);
		world.setBlock(baseX + 12, baseY + 5, baseZ + 8, Blocks.stonebrick, 0, 2);
		world.setBlock(baseX + 12, baseY + 6, baseZ + 5, Blocks.stonebrick, 0, 2);
		world.setBlock(baseX + 12, baseY + 6, baseZ + 8, Blocks.stonebrick, 0, 2);
		world.setBlock(baseX + 12, baseY + 7, baseZ + 5, Blocks.stonebrick, 0, 2);
		world.setBlock(baseX + 12, baseY + 7, baseZ + 6, Blocks.stone_brick_stairs, 7, 2);
		world.setBlock(baseX + 12, baseY + 7, baseZ + 7, Blocks.stone_brick_stairs, 6, 2);
		world.setBlock(baseX + 12, baseY + 7, baseZ + 8, Blocks.stonebrick, 0, 2);
		world.setBlock(baseX + 12, baseY + 8, baseZ + 2, Blocks.stone_brick_stairs, 4, 2);
		world.setBlock(baseX + 12, baseY + 8, baseZ + 6, Blocks.stone_brick_stairs, 2, 2);
		world.setBlock(baseX + 12, baseY + 8, baseZ + 7, Blocks.stone_brick_stairs, 3, 2);
		world.setBlock(baseX + 12, baseY + 8, baseZ + 11, Blocks.stone_brick_stairs, 4, 2);
		world.setBlock(baseX + 12, baseY + 9, baseZ + 2, Blocks.stonebrick, 0, 2);
		world.setBlock(baseX + 12, baseY + 9, baseZ + 11, Blocks.stonebrick, 0, 2);
		world.setBlock(baseX + 12, baseY + 10, baseZ + 2, Blocks.spruce_stairs, 2, 2);
		world.setBlock(baseX + 12, baseY + 10, baseZ + 3, Blocks.spruce_stairs, 7, 2);
		world.setBlock(baseX + 12, baseY + 10, baseZ + 10, Blocks.spruce_stairs, 6, 2);
		world.setBlock(baseX + 12, baseY + 10, baseZ + 11, Blocks.spruce_stairs, 3, 2);
		world.setBlock(baseX + 12, baseY + 11, baseZ + 3, Blocks.spruce_stairs, 2, 2);
		world.setBlock(baseX + 12, baseY + 11, baseZ + 4, Blocks.spruce_stairs, 7, 2);
		world.setBlock(baseX + 12, baseY + 11, baseZ + 9, Blocks.spruce_stairs, 6, 2);
		world.setBlock(baseX + 12, baseY + 11, baseZ + 10, Blocks.spruce_stairs, 3, 2);
		world.setBlock(baseX + 12, baseY + 12, baseZ + 4, Blocks.spruce_stairs, 2, 2);
		world.setBlock(baseX + 12, baseY + 12, baseZ + 5, Blocks.spruce_stairs, 7, 2);
		world.setBlock(baseX + 12, baseY + 12, baseZ + 8, Blocks.spruce_stairs, 6, 2);
		world.setBlock(baseX + 12, baseY + 12, baseZ + 9, Blocks.spruce_stairs, 3, 2);
		world.setBlock(baseX + 12, baseY + 13, baseZ + 5, Blocks.spruce_stairs, 2, 2);
		world.setBlock(baseX + 12, baseY + 13, baseZ + 6, Blocks.spruce_stairs, 7, 2);
		world.setBlock(baseX + 12, baseY + 13, baseZ + 7, Blocks.spruce_stairs, 6, 2);
		world.setBlock(baseX + 12, baseY + 13, baseZ + 8, Blocks.spruce_stairs, 3, 2);
		world.setBlock(baseX + 13, baseY + 1, baseZ + 0, Blocks.stonebrick, 0, 2);
		world.setBlock(baseX + 13, baseY + 1, baseZ + 2, Blocks.stonebrick, 0, 2);
		world.setBlock(baseX + 13, baseY + 1, baseZ + 3, Blocks.stonebrick, 0, 2);
		world.setBlock(baseX + 13, baseY + 1, baseZ + 4, Blocks.stonebrick, 0, 2);
		world.setBlock(baseX + 13, baseY + 1, baseZ + 5, Blocks.stonebrick, 0, 2);
		world.setBlock(baseX + 13, baseY + 1, baseZ + 6, Blocks.stonebrick, 0, 2);
		world.setBlock(baseX + 13, baseY + 1, baseZ + 7, Blocks.stonebrick, 0, 2);
		world.setBlock(baseX + 13, baseY + 1, baseZ + 8, Blocks.stonebrick, 0, 2);
		world.setBlock(baseX + 13, baseY + 1, baseZ + 9, Blocks.stonebrick, 0, 2);
		world.setBlock(baseX + 13, baseY + 1, baseZ + 10, Blocks.stonebrick, 0, 2);
		world.setBlock(baseX + 13, baseY + 1, baseZ + 11, Blocks.stonebrick, 0, 2);
		world.setBlock(baseX + 13, baseY + 1, baseZ + 13, Blocks.stonebrick, 0, 2);
		world.setBlock(baseX + 13, baseY + 2, baseZ + 0, Blocks.stonebrick, 0, 2);
		world.setBlock(baseX + 13, baseY + 2, baseZ + 2, Blocks.stonebrick, 0, 2);
		world.setBlock(baseX + 13, baseY + 2, baseZ + 3, Blocks.stonebrick, 0, 2);
		world.setBlock(baseX + 13, baseY + 2, baseZ + 4, Blocks.stonebrick, 0, 2);
		world.setBlock(baseX + 13, baseY + 2, baseZ + 5, Blocks.stonebrick, 0, 2);
		world.setBlock(baseX + 13, baseY + 2, baseZ + 6, Blocks.stonebrick, 0, 2);
		world.setBlock(baseX + 13, baseY + 2, baseZ + 7, Blocks.stonebrick, 0, 2);
		world.setBlock(baseX + 13, baseY + 2, baseZ + 8, Blocks.stonebrick, 0, 2);
		world.setBlock(baseX + 13, baseY + 2, baseZ + 9, Blocks.stonebrick, 0, 2);
		world.setBlock(baseX + 13, baseY + 2, baseZ + 10, Blocks.stonebrick, 0, 2);
		world.setBlock(baseX + 13, baseY + 2, baseZ + 11, Blocks.stonebrick, 0, 2);
		world.setBlock(baseX + 13, baseY + 2, baseZ + 13, Blocks.stonebrick, 0, 2);
		world.setBlock(baseX + 13, baseY + 3, baseZ + 0, Blocks.stonebrick, 0, 2);
		world.setBlock(baseX + 13, baseY + 3, baseZ + 2, Blocks.stonebrick, 0, 2);
		world.setBlock(baseX + 13, baseY + 3, baseZ + 3, Blocks.stonebrick, 0, 2);
		world.setBlock(baseX + 13, baseY + 3, baseZ + 4, Blocks.stonebrick, 0, 2);
		world.setBlock(baseX + 13, baseY + 3, baseZ + 6, Blocks.stonebrick, 0, 2);
		world.setBlock(baseX + 13, baseY + 3, baseZ + 7, Blocks.stonebrick, 0, 2);
		world.setBlock(baseX + 13, baseY + 3, baseZ + 9, Blocks.stonebrick, 0, 2);
		world.setBlock(baseX + 13, baseY + 3, baseZ + 10, Blocks.stonebrick, 0, 2);
		world.setBlock(baseX + 13, baseY + 3, baseZ + 11, Blocks.stonebrick, 0, 2);
		world.setBlock(baseX + 13, baseY + 3, baseZ + 13, Blocks.stonebrick, 0, 2);
		world.setBlock(baseX + 13, baseY + 4, baseZ + 0, Blocks.stonebrick, 0, 2);
		world.setBlock(baseX + 13, baseY + 4, baseZ + 2, Blocks.stonebrick, 0, 2);
		world.setBlock(baseX + 13, baseY + 4, baseZ + 3, Blocks.stonebrick, 0, 2);
		world.setBlock(baseX + 13, baseY + 4, baseZ + 4, Blocks.stonebrick, 0, 2);
		world.setBlock(baseX + 13, baseY + 4, baseZ + 6, Blocks.stonebrick, 0, 2);
		world.setBlock(baseX + 13, baseY + 4, baseZ + 7, Blocks.stonebrick, 0, 2);
		world.setBlock(baseX + 13, baseY + 4, baseZ + 9, Blocks.stonebrick, 0, 2);
		world.setBlock(baseX + 13, baseY + 4, baseZ + 10, Blocks.stonebrick, 0, 2);
		world.setBlock(baseX + 13, baseY + 4, baseZ + 11, Blocks.stonebrick, 0, 2);
		world.setBlock(baseX + 13, baseY + 4, baseZ + 13, Blocks.stonebrick, 0, 2);
		world.setBlock(baseX + 13, baseY + 5, baseZ + 0, Blocks.stone_brick_stairs, 2, 2);
		world.setBlock(baseX + 13, baseY + 5, baseZ + 1, Blocks.stone_brick_stairs, 7, 2);
		world.setBlock(baseX + 13, baseY + 5, baseZ + 2, Blocks.stonebrick, 0, 2);
		world.setBlock(baseX + 13, baseY + 5, baseZ + 3, Blocks.stonebrick, 0, 2);
		world.setBlock(baseX + 13, baseY + 5, baseZ + 4, Blocks.stonebrick, 0, 2);
		world.setBlock(baseX + 13, baseY + 5, baseZ + 6, Blocks.stonebrick, 0, 2);
		world.setBlock(baseX + 13, baseY + 5, baseZ + 7, Blocks.stonebrick, 0, 2);
		world.setBlock(baseX + 13, baseY + 5, baseZ + 9, Blocks.stonebrick, 0, 2);
		world.setBlock(baseX + 13, baseY + 5, baseZ + 10, Blocks.stonebrick, 0, 2);
		world.setBlock(baseX + 13, baseY + 5, baseZ + 11, Blocks.stonebrick, 0, 2);
		world.setBlock(baseX + 13, baseY + 5, baseZ + 12, Blocks.stone_brick_stairs, 6, 2);
		world.setBlock(baseX + 13, baseY + 5, baseZ + 13, Blocks.stone_brick_stairs, 3, 2);
		world.setBlock(baseX + 13, baseY + 6, baseZ + 1, Blocks.stone_brick_stairs, 2, 2);
		world.setBlock(baseX + 13, baseY + 6, baseZ + 2, Blocks.stonebrick, 0, 2);
		world.setBlock(baseX + 13, baseY + 6, baseZ + 3, Blocks.stonebrick, 0, 2);
		world.setBlock(baseX + 13, baseY + 6, baseZ + 4, Blocks.stonebrick, 0, 2);
		world.setBlock(baseX + 13, baseY + 6, baseZ + 6, Blocks.stonebrick, 0, 2);
		world.setBlock(baseX + 13, baseY + 6, baseZ + 7, Blocks.stonebrick, 0, 2);
		world.setBlock(baseX + 13, baseY + 6, baseZ + 9, Blocks.stonebrick, 0, 2);
		world.setBlock(baseX + 13, baseY + 6, baseZ + 10, Blocks.stonebrick, 0, 2);
		world.setBlock(baseX + 13, baseY + 6, baseZ + 11, Blocks.stonebrick, 0, 2);
		world.setBlock(baseX + 13, baseY + 6, baseZ + 12, Blocks.stone_brick_stairs, 3, 2);
		world.setBlock(baseX + 13, baseY + 7, baseZ + 2, Blocks.stonebrick, 0, 2);
		world.setBlock(baseX + 13, baseY + 7, baseZ + 3, Blocks.stonebrick, 0, 2);
		world.setBlock(baseX + 13, baseY + 7, baseZ + 4, Blocks.stonebrick, 0, 2);
		world.setBlock(baseX + 13, baseY + 7, baseZ + 6, Blocks.stonebrick, 0, 2);
		world.setBlock(baseX + 13, baseY + 7, baseZ + 7, Blocks.stonebrick, 0, 2);
		world.setBlock(baseX + 13, baseY + 7, baseZ + 9, Blocks.stonebrick, 0, 2);
		world.setBlock(baseX + 13, baseY + 7, baseZ + 10, Blocks.stonebrick, 0, 2);
		world.setBlock(baseX + 13, baseY + 7, baseZ + 11, Blocks.stonebrick, 0, 2);
		world.setBlock(baseX + 13, baseY + 8, baseZ + 2, Blocks.stonebrick, 0, 2);
		world.setBlock(baseX + 13, baseY + 8, baseZ + 3, Blocks.stonebrick, 0, 2);
		world.setBlock(baseX + 13, baseY + 8, baseZ + 4, Blocks.stonebrick, 0, 2);
		world.setBlock(baseX + 13, baseY + 8, baseZ + 5, Blocks.stonebrick, 0, 2);
		world.setBlock(baseX + 13, baseY + 8, baseZ + 6, Blocks.stonebrick, 0, 2);
		world.setBlock(baseX + 13, baseY + 8, baseZ + 7, Blocks.stonebrick, 0, 2);
		world.setBlock(baseX + 13, baseY + 8, baseZ + 8, Blocks.stonebrick, 0, 2);
		world.setBlock(baseX + 13, baseY + 8, baseZ + 9, Blocks.stonebrick, 0, 2);
		world.setBlock(baseX + 13, baseY + 8, baseZ + 10, Blocks.stonebrick, 0, 2);
		world.setBlock(baseX + 13, baseY + 8, baseZ + 11, Blocks.stonebrick, 0, 2);
		world.setBlock(baseX + 13, baseY + 9, baseZ + 2, Blocks.stonebrick, 0, 2);
		world.setBlock(baseX + 13, baseY + 9, baseZ + 3, Blocks.stonebrick, 0, 2);
		world.setBlock(baseX + 13, baseY + 9, baseZ + 4, Blocks.stonebrick, 0, 2);
		world.setBlock(baseX + 13, baseY + 9, baseZ + 5, Blocks.stonebrick, 0, 2);
		world.setBlock(baseX + 13, baseY + 9, baseZ + 6, Blocks.stonebrick, 0, 2);
		world.setBlock(baseX + 13, baseY + 9, baseZ + 7, Blocks.stonebrick, 0, 2);
		world.setBlock(baseX + 13, baseY + 9, baseZ + 8, Blocks.stonebrick, 0, 2);
		world.setBlock(baseX + 13, baseY + 9, baseZ + 9, Blocks.stonebrick, 0, 2);
		world.setBlock(baseX + 13, baseY + 9, baseZ + 10, Blocks.stonebrick, 0, 2);
		world.setBlock(baseX + 13, baseY + 9, baseZ + 11, Blocks.stonebrick, 0, 2);
		world.setBlock(baseX + 13, baseY + 10, baseZ + 2, Blocks.stone_brick_stairs, 2, 2);
		world.setBlock(baseX + 13, baseY + 10, baseZ + 3, Blocks.stonebrick, 0, 2);
		world.setBlock(baseX + 13, baseY + 10, baseZ + 4, Blocks.stonebrick, 0, 2);
		world.setBlock(baseX + 13, baseY + 10, baseZ + 5, Blocks.stonebrick, 0, 2);
		world.setBlock(baseX + 13, baseY + 10, baseZ + 8, Blocks.stonebrick, 0, 2);
		world.setBlock(baseX + 13, baseY + 10, baseZ + 9, Blocks.stonebrick, 0, 2);
		world.setBlock(baseX + 13, baseY + 10, baseZ + 10, Blocks.stonebrick, 0, 2);
		world.setBlock(baseX + 13, baseY + 10, baseZ + 11, Blocks.stone_brick_stairs, 3, 2);
		world.setBlock(baseX + 13, baseY + 11, baseZ + 3, Blocks.stone_brick_stairs, 2, 2);
		world.setBlock(baseX + 13, baseY + 11, baseZ + 4, Blocks.stonebrick, 0, 2);
		world.setBlock(baseX + 13, baseY + 11, baseZ + 5, Blocks.stonebrick, 0, 2);
		world.setBlock(baseX + 13, baseY + 11, baseZ + 8, Blocks.stonebrick, 0, 2);
		world.setBlock(baseX + 13, baseY + 11, baseZ + 9, Blocks.stonebrick, 0, 2);
		world.setBlock(baseX + 13, baseY + 11, baseZ + 10, Blocks.stone_brick_stairs, 3, 2);
		world.setBlock(baseX + 13, baseY + 12, baseZ + 4, Blocks.stone_brick_stairs, 2, 2);
		world.setBlock(baseX + 13, baseY + 12, baseZ + 5, Blocks.stonebrick, 0, 2);
		world.setBlock(baseX + 13, baseY + 12, baseZ + 8, Blocks.stonebrick, 0, 2);
		world.setBlock(baseX + 13, baseY + 12, baseZ + 9, Blocks.stone_brick_stairs, 3, 2);
		world.setBlock(baseX + 13, baseY + 13, baseZ + 5, Blocks.stone_brick_stairs, 2, 2);
		world.setBlock(baseX + 13, baseY + 13, baseZ + 6, Blocks.stone_brick_stairs, 7, 2);
		world.setBlock(baseX + 13, baseY + 13, baseZ + 7, Blocks.stone_brick_stairs, 6, 2);
		world.setBlock(baseX + 13, baseY + 13, baseZ + 8, Blocks.stone_brick_stairs, 3, 2);
		world.setBlockMetadataWithNotify(baseX + 1, baseY + 1, baseZ + 6, 2, 2);
		world.setBlockMetadataWithNotify(baseX + 1, baseY + 1, baseZ + 7, 2, 2);
		world.setBlockMetadataWithNotify(baseX + 1, baseY + 2, baseZ + 6, 9, 2);
		world.setBlockMetadataWithNotify(baseX + 1, baseY + 2, baseZ + 7, 8, 2);
		world.setBlockMetadataWithNotify(baseX + 2, baseY + 3, baseZ + 5, 1, 2);
		world.setBlockMetadataWithNotify(baseX + 2, baseY + 3, baseZ + 8, 1, 2);
		world.setBlockMetadataWithNotify(baseX + 2, baseY + 7, baseZ + 5, 1, 2);
		world.setBlockMetadataWithNotify(baseX + 2, baseY + 7, baseZ + 8, 1, 2);
		world.setBlockMetadataWithNotify(baseX + 2, baseY + 11, baseZ + 5, 1, 2);
		world.setBlockMetadataWithNotify(baseX + 2, baseY + 11, baseZ + 8, 1, 2);
		world.setBlockMetadataWithNotify(baseX + 5, baseY + 3, baseZ + 3, 3, 2);
		world.setBlockMetadataWithNotify(baseX + 5, baseY + 3, baseZ + 10, 4, 2);
		world.setBlockMetadataWithNotify(baseX + 5, baseY + 7, baseZ + 3, 3, 2);
		world.setBlockMetadataWithNotify(baseX + 5, baseY + 7, baseZ + 10, 4, 2);
		world.setBlockMetadataWithNotify(baseX + 9, baseY + 3, baseZ + 3, 3, 2);
		world.setBlockMetadataWithNotify(baseX + 9, baseY + 3, baseZ + 10, 4, 2);
		world.setBlockMetadataWithNotify(baseX + 9, baseY + 7, baseZ + 3, 3, 2);
		world.setBlockMetadataWithNotify(baseX + 9, baseY + 7, baseZ + 10, 4, 2);
		world.setBlockMetadataWithNotify(baseX + 11, baseY + 3, baseZ + 5, 2, 2);
		world.setBlockMetadataWithNotify(baseX + 11, baseY + 3, baseZ + 8, 2, 2);
		world.setBlockMetadataWithNotify(baseX + 12, baseY + 11, baseZ + 5, 2, 2);
		world.setBlockMetadataWithNotify(baseX + 12, baseY + 11, baseZ + 8, 2, 2);
		
		
		
	}

	private void clearUp(World world, int x, int y, int z)
	{
		if(world.getBlock(x, y, z) != Blocks.air)
		{
			world.setBlock(x, y, z, Blocks.air);
			clearUp(world, x, y + 1, z);
		}
		
		
	}

}
